Workbook

Sheet Mode d'emploi
B2: DSCG 1 — Suivi des révisions (diagramme de Gantt)
B3: Classeur prêt à l'emploi pour planifier, visualiser et suivre tes révisions par UE jusqu'aux examens.
B5: 1. Paramètres
B6: Ouvre l'onglet Paramètres. Indique ta date de début de révision et la date d'examen. Les 16 semaines du Gantt se recalculent automatiquement.
B8: 2. Planning Gantt
B9: Chaque ligne = un thème de révision. Modifie UE, thème, type, priorité, dates de début/fin et % d'avancement. Les barres colorées se mettent à jour toutes seules.
B11: 3. Couleurs du Gantt
B12: Bleu = planifié | Vert = terminé (≥100 %) | Orange = en cours | Rouge = en retard (date de fin dépassée et avancement < 100 %).
B14: 4. Tableau de bord
B15: L'onglet Tableau de bord résume ta progression globale, par UE et les thèmes en retard. Actualise les filtres si besoin (données → actualiser).
B17: 5. Personnalisation
B18: Ajoute des lignes sous les thèmes existants (copie une ligne pour garder les formules du Gantt). Tu peux supprimer les thèmes qui ne concernent pas tes UE.
... B29: • Bibliothèque UE → idées de thèmes par unité d'enseignement

Sheet Paramètres
B2: Paramètres du planning
B4: Prénom / Identifiant | C4: Élève DSCG 1 | D4: Ton nom (optionnel)
B5: Date de début des révisions | C5: 46027 | D5: Doit être un lundi de préférence
B6: Date d'examen (1ère épreuve) | C6: 46146 | D6: Date butoir affichée dans le Gantt
B7: Heures dispo / semaine | C7: 12 | D7: Pour estimer la charge (info)
B8: Objectif d'avancement global | C8: 1 | D8: Ex. 100 % = tout terminé
B10: Calendrier des semaines (calculé automatiquement)
B11: N° semaine | C11: Date de début (lundi) | D11: Libellé Gantt
B12: 1 | C12: =$C$5+(1-1)*7 | D12: ="S"&B12&" "&TEXT(C12,"DD/MM")
B13: 2 | C13: =$C$5+(2-1)*7 | D13: ="S"&B13&" "&TEXT(C13,"DD/MM")
B14: 3 | C14: =$C$5+(3-1)*7 | D14: ="S"&B14&" "&TEXT(C14,"DD/MM")
B15: 4 | C15: =$C$5+(4-1)*7 | D15: ="S"&B15&" "&TEXT(C15,"DD/MM")
B16: 5 | C16: =$C$5+(5-1)*7 | D16: ="S"&B16&" "&TEXT(C16,"DD/MM")
B17: 6 | C17: =$C$5+(6-1)*7 | D17: ="S"&B17&" "&TEXT(C17,"DD/MM")
B18: 7 | C18: =$C$5+(7-1)*7 | D18: ="S"&B18&" "&TEXT(C18,"DD/MM")
B19: 8 | C19: =$C$5+(8-1)*7 | D19: ="S"&B19&" "&TEXT(C19,"DD/MM")
B20: 9 | C20: =$C$5+(9-1)*7 | D20: ="S"&B20&" "&TEXT(C20,"DD/MM")
B21: 10 | C21: =$C$5+(10-1)*7 | D21: ="S"&B21&" "&TEXT(C21,"DD/MM")
B22: 11 | C22: =$C$5+(11-1)*7 | D22: ="S"&B22&" "&TEXT(C22,"DD/MM")
B23: 12 | C23: =$C$5+(12-1)*7 | D23: ="S"&B23&" "&TEXT(C23,"DD/MM")
B24: 13 | C24: =$C$5+(13-1)*7 | D24: ="S"&B24&" "&TEXT(C24,"DD/MM")
B25: 14 | C25: =$C$5+(14-1)*7 | D25: ="S"&B25&" "&TEXT(C25,"DD/MM")
B26: 15 | C26: =$C$5+(15-1)*7 | D26: ="S"&B26&" "&TEXT(C26,"DD/MM")
B27: 16 | C27: =$C$5+(16-1)*7 | D27: ="S"&B27&" "&TEXT(C27,"DD/MM")
B29: Ne renomme pas cet onglet ni les cellules C5/C6 : le Planning Gantt s'y réfère.
B30: Cellules clés utilisées par les formules
B31: DateDebut | C31: =C5
B32: DateExamen | C32: =C6

Sheet Planning Gantt
B2: Planning Gantt — Révisions DSCG 1
B3: Semaines calculées depuis Paramètres!C5 • Remplis les colonnes jaunes • Les barres se colorent automatiquement
B4: UE | C4: Thème / Chapitre | D4: Type | E4: Priorité | F4: Début | G4: Fin | H4: Avancement | I4: Statut | J4: Jours restants | K4: =Paramètres!D12 | L4: =Paramètres!D13 | M4: =Paramètres!D14 | N4: =Paramètres!D15 | O4: =Paramètres!D16 | P4: =Paramètres!D17 | Q4: =Paramètres!D18 | R4: =Paramètres!D19 | S4: =Paramètres!D20 | T4: =Paramètres!D21 | U4: =Paramètres!D22 | V4: =Paramètres!D23 | W4: =Paramètres!D24 | X4: =Paramètres!D25 | Y4: =Paramètres!D26 | Z4: =Paramètres!D27
B5: UE1 | C5: Droit des sociétés — constitution & fonctionnement | D5: Cours | E5: Haute | F5: =Paramètres!$C$5+(1-1)*7 | G5: =Paramètres!$C$5+(2)*7-1 | H5: 0 | I5: =IF(C5="","",IF(H5>=1,"Terminé",IF(AND(G5<>"",G5<TODAY(),H5<1),"En retard",IF(H5>0,"En cours","À faire")))) | J5: =IF(OR(C5="",G5=""),"",G5-TODAY()) | K5: =IF(OR($C5="",$F5="",$G5=""),"",IF(AND($F5<=Paramètres!$C$12+6,$G5>=Paramètres!$C$12),1,"")) | L5: =IF(OR($C5="",$F5="",$G5=""),"",IF(AND($F5<=Paramètres!$C$13+6,$G5>=Paramètres!$C$13),1,"")) | M5: =IF(OR($C5="",$F5="",$G5=""),"",IF(AND($F5<=Paramètres!$C$14+6,$G5>=Paramètres!$C$14),1,"")) | N5: =IF(OR($C5="",$F5="",$G5=""),"",IF(AND($F5<=Paramètres!$C$15+6,$G5>=Paramètres!$C$15),1,"")) | O5: =IF(OR($C5="",$F5="",$G5=""),"",IF(AND($F5<=Paramètres!$C$16+6,$G5>=Paramètres!$C$16),1,"")) | P5: =IF(OR($C5="",$F5="",$G5=""),"",IF(AND($F5<=Paramètres!$C$17+6,$G5>=Paramètres!$C$17),1,"")) | Q5: =IF(OR($C5="",$F5="",$G5=""),"",IF(AND($F5<=Paramètres!$C$18+6,$G5>=Paramètres!$C$18),1,"")) | R5: =IF(OR($C5="",$F5="",$G5=""),"",IF(AND($F5<=Paramètres!$C$19+6,$G5>=Paramètres!$C$19),1,"")) | S5: =IF(OR($C5="",$F5="",$G5=""),"",IF(AND($F5<=Paramètres!$C$20+6,$G5>=Paramètres!$C$20),1,"")) | T5: =IF(OR($C5="",$F5="",$G5=""),"",IF(AND($F5<=Paramètres!$C$21+6,$G5>=Paramètres!$C$21),1,"")) | U5: =IF(OR($C5="",$F5="",$G5=""),"",IF(AND($F5<=Paramètres!$C$22+6,$G5>=Paramètres!$C$22),1,"")) | V5: =IF(OR($C5="",$F5="",$G5=""),"",IF(AND($F5<=Paramètres!$C$23+6,$G5>=Paramètres!$C$23),1,"")) | W5: =IF(OR($C5="",$F5="",$G5=""),"",IF(AND($F5<=Paramètres!$C$24+6,$G5>=Paramètres!$C$24),1,"")) | X5: =IF(OR($C5="",$F5="",$G5=""),"",IF(AND($F5<=Paramètres!$C$25+6,$G5>=Paramètres!$C$25),1,"")) | Y5: =IF(OR($C5="",$F5="",$G5=""),"",IF(AND($F5<=Paramètres!$C$26+6,$G5>=Paramètres!$C$26),1,"")) | Z5: =IF(OR($C5="",$F5="",$G5=""),"",IF(AND($F5<=Paramètres!$C$27+6,$G5>=Paramètres!$C$27),1,""))
B6: UE1 | C6: Droit des sociétés — fusions, scissions, dissolution | D6: Cours | E6: Haute | F6: =Paramètres!$C$5+(3-1)*7 | G6: =Paramètres!$C$5+(3)*7-1 | H6: 0 | I6: =IF(C6="","",IF(H6>=1,"Terminé",IF(AND(G6<>"",G6<TODAY(),H6<1),"En retard",IF(H6>0,"En cours","À faire")))) | J6: =IF(OR(C6="",G6=""),"",G6-TODAY()) | K6: =IF(OR($C6="",$F6="",$G6=""),"",IF(AND($F6<=Paramètres!$C$12+6,$G6>=Paramètres!$C$12),1,"")) | L6: =IF(OR($C6="",$F6="",$G6=""),"",IF(AND($F6<=Paramètres!$C$13+6,$G6>=Paramètres!$C$13),1,"")) | M6: =IF(OR($C6="",$F6="",$G6=""),"",IF(AND($F6<=Paramètres!$C$14+6,$G6>=Paramètres!$C$14),1,"")) | N6: =IF(OR($C6="",$F6="",$G6=""),"",IF(AND($F6<=Paramètres!$C$15+6,$G6>=Paramètres!$C$15),1,"")) | O6: =IF(OR($C6="",$F6="",$G6=""),"",IF(AND($F6<=Paramètres!$C$16+6,$G6>=Paramètres!$C$16),1,"")) | P6: =IF(OR($C6="",$F6="",$G6=""),"",IF(AND($F6<=Paramètres!$C$17+6,$G6>=Paramètres!$C$17),1,"")) | Q6: =IF(OR($C6="",$F6="",$G6=""),"",IF(AND($F6<=Paramètres!$C$18+6,$G6>=Paramètres!$C$18),1,"")) | R6: =IF(OR($C6="",$F6="",$G6=""),"",IF(AND($F6<=Paramètres!$C$19+6,$G6>=Paramètres!$C$19),1,"")) | S6: =IF(OR($C6="",$F6="",$G6=""),"",IF(AND($F6<=Paramètres!$C$20+6,$G6>=Paramètres!$C$20),1,"")) | T6: =IF(OR($C6="",$F6="",$G6=""),"",IF(AND($F6<=Paramètres!$C$21+6,$G6>=Paramètres!$C$21),1,"")) | U6: =IF(OR($C6="",$F6="",$G6=""),"",IF(AND($F6<=Paramètres!$C$22+6,$G6>=Paramètres!$C$22),1,"")) | V6: =IF(OR($C6="",$F6="",$G6=""),"",IF(AND($F6<=Paramètres!$C$23+6,$G6>=Paramètres!$C$23),1,"")) | W6: =IF(OR($C6="",$F6="",$G6=""),"",IF(AND($F6<=Paramètres!$C$24+6,$G6>=Paramètres!$C$24),1,"")) | X6: =IF(OR($C6="",$F6="",$G6=""),"",IF(AND($F6<=Paramètres!$C$25+6,$G6>=Paramètres!$C$25),1,"")) | Y6: =IF(OR($C6="",$F6="",$G6=""),"",IF(AND($F6<=Paramètres!$C$26+6,$G6>=Paramètres!$C$26),1,"")) | Z6: =IF(OR($C6="",$F6="",$G6=""),"",IF(AND($F6<=Paramètres!$C$27+6,$G6>=Paramètres!$C$27),1,""))
B7: UE1 | C7: Fiscalité des entreprises — IS & intégration fiscale | D7: Cours | E7: Haute | F7: =Paramètres!$C$5+(4-1)*7 | G7: =Paramètres!$C$5+(5)*7-1 | H7: 0 | I7: =IF(C7="","",IF(H7>=1,"Terminé",IF(AND(G7<>"",G7<TODAY(),H7<1),"En retard",IF(H7>0,"En cours","À faire")))) | J7: =IF(OR(C7="",G7=""),"",G7-TODAY()) | K7: =IF(OR($C7="",$F7="",$G7=""),"",IF(AND($F7<=Paramètres!$C$12+6,$G7>=Paramètres!$C$12),1,"")) | L7: =IF(OR($C7="",$F7="",$G7=""),"",IF(AND($F7<=Paramètres!$C$13+6,$G7>=Paramètres!$C$13),1,"")) | M7: =IF(OR($C7="",$F7="",$G7=""),"",IF(AND($F7<=Paramètres!$C$14+6,$G7>=Paramètres!$C$14),1,"")) | N7: =IF(OR($C7="",$F7="",$G7=""),"",IF(AND($F7<=Paramètres!$C$15+6,$G7>=Paramètres!$C$15),1,"")) | O7: =IF(OR($C7="",$F7="",$G7=""),"",IF(AND($F7<=Paramètres!$C$16+6,$G7>=Paramètres!$C$16),1,"")) | P7: =IF(OR($C7="",$F7="",$G7=""),"",IF(AND($F7<=Paramètres!$C$17+6,$G7>=Paramètres!$C$17),1,"")) | Q7: =IF(OR($C7="",$F7="",$G7=""),"",IF(AND($F7<=Paramètres!$C$18+6,$G7>=Paramètres!$C$18),1,"")) | R7: =IF(OR($C7="",$F7="",$G7=""),"",IF(AND($F7<=Paramètres!$C$19+6,$G7>=Paramètres!$C$19),1,"")) | S7: =IF(OR($C7="",$F7="",$G7=""),"",IF(AND($F7<=Paramètres!$C$20+6,$G7>=Paramètres!$C$20),1,"")) | T7: =IF(OR($C7="",$F7="",$G7=""),"",IF(AND($F7<=Paramètres!$C$21+6,$G7>=Paramètres!$C$21),1,"")) | U7: =IF(OR($C7="",$F7="",$G7=""),"",IF(AND($F7<=Paramètres!$C$22+6,$G7>=Paramètres!$C$22),1,"")) | V7: =IF(OR($C7="",$F7="",$G7=""),"",IF(AND($F7<=Paramètres!$C$23+6,$G7>=Paramètres!$C$23),1,"")) | W7: =IF(OR($C7="",$F7="",$G7=""),"",IF(AND($F7<=Paramètres!$C$24+6,$G7>=Paramètres!$C$24),1,"")) | X7: =IF(OR($C7="",$F7="",$G7=""),"",IF(AND($F7<=Paramètres!$C$25+6,$G7>=Paramètres!$C$25),1,"")) | Y7: =IF(OR($C7="",$F7="",$G7=""),"",IF(AND($F7<=Paramètres!$C$26+6,$G7>=Paramètres!$C$26),1,"")) | Z7: =IF(OR($C7="",$F7="",$G7=""),"",IF(AND($F7<=Paramètres!$C$27+6,$G7>=Paramètres!$C$27),1,""))
B8: UE1 | C8: Fiscalité — TVA & taxes diverses | D8: Exercices | E8: Moyenne | F8: =Paramètres!$C$5+(5-1)*7 | G8: =Paramètres!$C$5+(6)*7-1 | H8: 0 | I8: =IF(C8="","",IF(H8>=1,"Terminé",IF(AND(G8<>"",G8<TODAY(),H8<1),"En retard",IF(H8>0,"En cours","À faire")))) | J8: =IF(OR(C8="",G8=""),"",G8-TODAY()) | K8: =IF(OR($C8="",$F8="",$G8=""),"",IF(AND($F8<=Paramètres!$C$12+6,$G8>=Paramètres!$C$12),1,"")) | L8: =IF(OR($C8="",$F8="",$G8=""),"",IF(AND($F8<=Paramètres!$C$13+6,$G8>=Paramètres!$C$13),1,"")) | M8: =IF(OR($C8="",$F8="",$G8=""),"",IF(AND($F8<=Paramètres!$C$14+6,$G8>=Paramètres!$C$14),1,"")) | N8: =IF(OR($C8="",$F8="",$G8=""),"",IF(AND($F8<=Paramètres!$C$15+6,$G8>=Paramètres!$C$15),1,"")) | O8: =IF(OR($C8="",$F8="",$G8=""),"",IF(AND($F8<=Paramètres!$C$16+6,$G8>=Paramètres!$C$16),1,"")) | P8: =IF(OR($C8="",$F8="",$G8=""),"",IF(AND($F8<=Paramètres!$C$17+6,$G8>=Paramètres!$C$17),1,"")) | Q8: =IF(OR($C8="",$F8="",$G8=""),"",IF(AND($F8<=Paramètres!$C$18+6,$G8>=Paramètres!$C$18),1,"")) | R8: =IF(OR($C8="",$F8="",$G8=""),"",IF(AND($F8<=Paramètres!$C$19+6,$G8>=Paramètres!$C$19),1,"")) | S8: =IF(OR($C8="",$F8="",$G8=""),"",IF(AND($F8<=Paramètres!$C$20+6,$G8>=Paramètres!$C$20),1,"")) | T8: =IF(OR($C8="",$F8="",$G8=""),"",IF(AND($F8<=Paramètres!$C$21+6,$G8>=Paramètres!$C$21),1,"")) | U8: =IF(OR($C8="",$F8="",$G8=""),"",IF(AND($F8<=Paramètres!$C$22+6,$G8>=Paramètres!$C$22),1,"")) | V8: =IF(OR($C8="",$F8="",$G8=""),"",IF(AND($F8<=Paramètres!$C$23+6,$G8>=Paramètres!$C$23),1,"")) | W8: =IF(OR($C8="",$F8="",$G8=""),"",IF(AND($F8<=Paramètres!$C$24+6,$G8>=Paramètres!$C$24),1,"")) | X8: =IF(OR($C8="",$F8="",$G8=""),"",IF(AND($F8<=Paramètres!$C$25+6,$G8>=Paramètres!$C$25),1,"")) | Y8: =IF(OR($C8="",$F8="",$G8=""),"",IF(AND($F8<=Paramètres!$C$26+6,$G8>=Paramètres!$C$26),1,"")) | Z8: =IF(OR($C8="",$F8="",$G8=""),"",IF(AND($F8<=Paramètres!$C$27+6,$G8>=Paramètres!$C$27),1,""))
B9: UE1 | C9: Droit social — contrat de travail & rupture | D9: Cours | E9: Haute | F9: =Paramètres!$C$5+(7-1)*7 | G9: =Paramètres!$C$5+(8)*7-1 | H9: 0 | I9: =IF(C9="","",IF(H9>=1,"Terminé",IF(AND(G9<>"",G9<TODAY(),H9<1),"En retard",IF(H9>0,"En cours","À faire")))) | J9: =IF(OR(C9="",G9=""),"",G9-TODAY()) | K9: =IF(OR($C9="",$F9="",$G9=""),"",IF(AND($F9<=Paramètres!$C$12+6,$G9>=Paramètres!$C$12),1,"")) | L9: =IF(OR($C9="",$F9="",$G9=""),"",IF(AND($F9<=Paramètres!$C$13+6,$G9>=Paramètres!$C$13),1,"")) | M9: =IF(OR($C9="",$F9="",$G9=""),"",IF(AND($F9<=Paramètres!$C$14+6,$G9>=Paramètres!$C$14),1,"")) | N9: =IF(OR($C9="",$F9="",$G9=""),"",IF(AND($F9<=Paramètres!$C$15+6,$G9>=Paramètres!$C$15),1,"")) | O9: =IF(OR($C9="",$F9="",$G9=""),"",IF(AND($F9<=Paramètres!$C$16+6,$G9>=Paramètres!$C$16),1,"")) | P9: =IF(OR($C9="",$F9="",$G9=""),"",IF(AND($F9<=Paramètres!$C$17+6,$G9>=Paramètres!$C$17),1,"")) | Q9: =IF(OR($C9="",$F9="",$G9=""),"",IF(AND($F9<=Paramètres!$C$18+6,$G9>=Paramètres!$C$18),1,"")) | R9: =IF(OR($C9="",$F9="",$G9=""),"",IF(AND($F9<=Paramètres!$C$19+6,$G9>=Paramètres!$C$19),1,"")) | S9: =IF(OR($C9="",$F9="",$G9=""),"",IF(AND($F9<=Paramètres!$C$20+6,$G9>=Paramètres!$C$20),1,"")) | T9: =IF(OR($C9="",$F9="",$G9=""),"",IF(AND($F9<=Paramètres!$C$21+6,$G9>=Paramètres!$C$21),1,"")) | U9: =IF(OR($C9="",$F9="",$G9=""),"",IF(AND($F9<=Paramètres!$C$22+6,$G9>=Paramètres!$C$22),1,"")) | V9: =IF(OR($C9="",$F9="",$G9=""),"",IF(AND($F9<=Paramètres!$C$23+6,$G9>=Paramètres!$C$23),1,"")) | W9: =IF(OR($C9="",$F9="",$G9=""),"",IF(AND($F9<=Paramètres!$C$24+6,$G9>=Paramètres!$C$24),1,"")) | X9: =IF(OR($C9="",$F9="",$G9=""),"",IF(AND($F9<=Paramètres!$C$25+6,$G9>=Paramètres!$C$25),1,"")) | Y9: =IF(OR($C9="",$F9="",$G9=""),"",IF(AND($F9<=Paramètres!$C$26+6,$G9>=Paramètres!$C$26),1,"")) | Z9: =IF(OR($C9="",$F9="",$G9=""),"",IF(AND($F9<=Paramètres!$C$27+6,$G9>=Paramètres!$C$27),1,""))
B10: UE1 | C10: Annales UE1 — sujets blancs | D10: Annales | E10: Haute | F10: =Paramètres!$C$5+(14-1)*7 | G10: =Paramètres!$C$5+(15)*7-1 | H10: 0 | I10: =IF(C10="","",IF(H10>=1,"Terminé",IF(AND(G10<>"",G10<TODAY(),H10<1),"En retard",IF(H10>0,"En cours","À faire")))) | J10: =IF(OR(C10="",G10=""),"",G10-TODAY()) | K10: =IF(OR($C10="",$F10="",$G10=""),"",IF(AND($F10<=Paramètres!$C$12+6,$G10>=Paramètres!$C$12),1,"")) | L10: =IF(OR($C10="",$F10="",$G10=""),"",IF(AND($F10<=Paramètres!$C$13+6,$G10>=Paramètres!$C$13),1,"")) | M10: =IF(OR($C10="",$F10="",$G10=""),"",IF(AND($F10<=Paramètres!$C$14+6,$G10>=Paramètres!$C$14),1,"")) | N10: =IF(OR($C10="",$F10="",$G10=""),"",IF(AND($F10<=Paramètres!$C$15+6,$G10>=Paramètres!$C$15),1,"")) | O10: =IF(OR($C10="",$F10="",$G10=""),"",IF(AND($F10<=Paramètres!$C$16+6,$G10>=Paramètres!$C$16),1,"")) | P10: =IF(OR($C10="",$F10="",$G10=""),"",IF(AND($F10<=Paramètres!$C$17+6,$G10>=Paramètres!$C$17),1,"")) | Q10: =IF(OR($C10="",$F10="",$G10=""),"",IF(AND($F10<=Paramètres!$C$18+6,$G10>=Paramètres!$C$18),1,"")) | R10: =IF(OR($C10="",$F10="",$G10=""),"",IF(AND($F10<=Paramètres!$C$19+6,$G10>=Paramètres!$C$19),1,"")) | S10: =IF(OR($C10="",$F10="",$G10=""),"",IF(AND($F10<=Paramètres!$C$20+6,$G10>=Paramètres!$C$20),1,"")) | T10: =IF(OR($C10="",$F10="",$G10=""),"",IF(AND($F10<=Paramètres!$C$21+6,$G10>=Paramètres!$C$21),1,"")) | U10: =IF(OR($C10="",$F10="",$G10=""),"",IF(AND($F10<=Paramètres!$C$22+6,$G10>=Paramètres!$C$22),1,"")) | V10: =IF(OR($C10="",$F10="",$G10=""),"",IF(AND($F10<=Paramètres!$C$23+6,$G10>=Paramètres!$C$23),1,"")) | W10: =IF(OR($C10="",$F10="",$G10=""),"",IF(AND($F10<=Paramètres!$C$24+6,$G10>=Paramètres!$C$24),1,"")) | X10: =IF(OR($C10="",$F10="",$G10=""),"",IF(AND($F10<=Paramètres!$C$25+6,$G10>=Paramètres!$C$25),1,"")) | Y10: =IF(OR($C10="",$F10="",$G10=""),"",IF(AND($F10<=Paramètres!$C$26+6,$G10>=Paramètres!$C$26),1,"")) | Z10: =IF(OR($C10="",$F10="",$G10=""),"",IF(AND($F10<=Paramètres!$C$27+6,$G10>=Paramètres!$C$27),1,""))
B11: UE2 | C11: Diagnostic financier & tableaux de flux | D11: Cours | E11: Haute | F11: =Paramètres!$C$5+(1-1)*7 | G11: =Paramètres!$C$5+(2)*7-1 | H11: 0 | I11: =IF(C11="","",IF(H11>=1,"Terminé",IF(AND(G11<>"",G11<TODAY(),H11<1),"En retard",IF(H11>0,"En cours","À faire")))) | J11: =IF(OR(C11="",G11=""),"",G11-TODAY()) | K11: =IF(OR($C11="",$F11="",$G11=""),"",IF(AND($F11<=Paramètres!$C$12+6,$G11>=Paramètres!$C$12),1,"")) | L11: =IF(OR($C11="",$F11="",$G11=""),"",IF(AND($F11<=Paramètres!$C$13+6,$G11>=Paramètres!$C$13),1,"")) | M11: =IF(OR($C11="",$F11="",$G11=""),"",IF(AND($F11<=Paramètres!$C$14+6,$G11>=Paramètres!$C$14),1,"")) | N11: =IF(OR($C11="",$F11="",$G11=""),"",IF(AND($F11<=Paramètres!$C$15+6,$G11>=Paramètres!$C$15),1,"")) | O11: =IF(OR($C11="",$F11="",$G11=""),"",IF(AND($F11<=Paramètres!$C$16+6,$G11>=Paramètres!$C$16),1,"")) | P11: =IF(OR($C11="",$F11="",$G11=""),"",IF(AND($F11<=Paramètres!$C$17+6,$G11>=Paramètres!$C$17),1,"")) | Q11: =IF(OR($C11="",$F11="",$G11=""),"",IF(AND($F11<=Paramètres!$C$18+6,$G11>=Paramètres!$C$18),1,"")) | R11: =IF(OR($C11="",$F11="",$G11=""),"",IF(AND($F11<=Paramètres!$C$19+6,$G11>=Paramètres!$C$19),1,"")) | S11: =IF(OR($C11="",$F11="",$G11=""),"",IF(AND($F11<=Paramètres!$C$20+6,$G11>=Paramètres!$C$20),1,"")) | T11: =IF(OR($C11="",$F11="",$G11=""),"",IF(AND($F11<=Paramètres!$C$21+6,$G11>=Paramètres!$C$21),1,"")) | U11: =IF(OR($C11="",$F11="",$G11=""),"",IF(AND($F11<=Paramètres!$C$22+6,$G11>=Paramètres!$C$22),1,"")) | V11: =IF(OR($C11="",$F11="",$G11=""),"",IF(AND($F11<=Paramètres!$C$23+6,$G11>=Paramètres!$C$23),1,"")) | W11: =IF(OR($C11="",$F11="",$G11=""),"",IF(AND($F11<=Paramètres!$C$24+6,$G11>=Paramètres!$C$24),1,"")) | X11: =IF(OR($C11="",$F11="",$G11=""),"",IF(AND($F11<=Paramètres!$C$25+6,$G11>=Paramètres!$C$25),1,"")) | Y11: =IF(OR($C11="",$F11="",$G11=""),"",IF(AND($F11<=Paramètres!$C$26+6,$G11>=Paramètres!$C$26),1,"")) | Z11: =IF(OR($C11="",$F11="",$G11=""),"",IF(AND($F11<=Paramètres!$C$27+6,$G11>=Paramètres!$C$27),1,""))
B12: UE2 | C12: Évaluation d'entreprise | D12: Cours | E12: Haute | F12: =Paramètres!$C$5+(3-1)*7 | G12: =Paramètres!$C$5+(4)*7-1 | H12: 0 | I12: =IF(C12="","",IF(H12>=1,"Terminé",IF(AND(G12<>"",G12<TODAY(),H12<1),"En retard",IF(H12>0,"En cours","À faire")))) | J12: =IF(OR(C12="",G12=""),"",G12-TODAY()) | K12: =IF(OR($C12="",$F12="",$G12=""),"",IF(AND($F12<=Paramètres!$C$12+6,$G12>=Paramètres!$C$12),1,"")) | L12: =IF(OR($C12="",$F12="",$G12=""),"",IF(AND($F12<=Paramètres!$C$13+6,$G12>=Paramètres!$C$13),1,"")) | M12: =IF(OR($C12="",$F12="",$G12=""),"",IF(AND($F12<=Paramètres!$C$14+6,$G12>=Paramètres!$C$14),1,"")) | N12: =IF(OR($C12="",$F12="",$G12=""),"",IF(AND($F12<=Paramètres!$C$15+6,$G12>=Paramètres!$C$15),1,"")) | O12: =IF(OR($C12="",$F12="",$G12=""),"",IF(AND($F12<=Paramètres!$C$16+6,$G12>=Paramètres!$C$16),1,"")) | P12: =IF(OR($C12="",$F12="",$G12=""),"",IF(AND($F12<=Paramètres!$C$17+6,$G12>=Paramètres!$C$17),1,"")) | Q12: =IF(OR($C12="",$F12="",$G12=""),"",IF(AND($F12<=Paramètres!$C$18+6,$G12>=Paramètres!$C$18),1,"")) | R12: =IF(OR($C12="",$F12="",$G12=""),"",IF(AND($F12<=Paramètres!$C$19+6,$G12>=Paramètres!$C$19),1,"")) | S12: =IF(OR($C12="",$F12="",$G12=""),"",IF(AND($F12<=Paramètres!$C$20+6,$G12>=Paramètres!$C$20),1,"")) | T12: =IF(OR($C12="",$F12="",$G12=""),"",IF(AND($F12<=Paramètres!$C$21+6,$G12>=Paramètres!$C$21),1,"")) | U12: =IF(OR($C12="",$F12="",$G12=""),"",IF(AND($F12<=Paramètres!$C$22+6,$G12>=Paramètres!$C$22),1,"")) | V12: =IF(OR($C12="",$F12="",$G12=""),"",IF(AND($F12<=Paramètres!$C$23+6,$G12>=Paramètres!$C$23),1,"")) | W12: =IF(OR($C12="",$F12="",$G12=""),"",IF(AND($F12<=Paramètres!$C$24+6,$G12>=Paramètres!$C$24),1,"")) | X12: =IF(OR($C12="",$F12="",$G12=""),"",IF(AND($F12<=Paramètres!$C$25+6,$G12>=Paramètres!$C$25),1,"")) | Y12: =IF(OR($C12="",$F12="",$G12=""),"",IF(AND($F12<=Paramètres!$C$26+6,$G12>=Paramètres!$C$26),1,"")) | Z12: =IF(OR($C12="",$F12="",$G12=""),"",IF(AND($F12<=Paramètres!$C$27+6,$G12>=Paramètres!$C$27),1,""))
B13: UE2 | C13: Politique d'investissement & VAN/TRI | D13: Exercices | E13: Haute | F13: =Paramètres!$C$5+(5-1)*7 | G13: =Paramètres!$C$5+(6)*7-1 | H13: 0 | I13: =IF(C13="","",IF(H13>=1,"Terminé",IF(AND(G13<>"",G13<TODAY(),H13<1),"En retard",IF(H13>0,"En cours","À faire")))) | J13: =IF(OR(C13="",G13=""),"",G13-TODAY()) | K13: =IF(OR($C13="",$F13="",$G13=""),"",IF(AND($F13<=Paramètres!$C$12+6,$G13>=Paramètres!$C$12),1,"")) | L13: =IF(OR($C13="",$F13="",$G13=""),"",IF(AND($F13<=Paramètres!$C$13+6,$G13>=Paramètres!$C$13),1,"")) | M13: =IF(OR($C13="",$F13="",$G13=""),"",IF(AND($F13<=Paramètres!$C$14+6,$G13>=Paramètres!$C$14),1,"")) | N13: =IF(OR($C13="",$F13="",$G13=""),"",IF(AND($F13<=Paramètres!$C$15+6,$G13>=Paramètres!$C$15),1,"")) | O13: =IF(OR($C13="",$F13="",$G13=""),"",IF(AND($F13<=Paramètres!$C$16+6,$G13>=Paramètres!$C$16),1,"")) | P13: =IF(OR($C13="",$F13="",$G13=""),"",IF(AND($F13<=Paramètres!$C$17+6,$G13>=Paramètres!$C$17),1,"")) | Q13: =IF(OR($C13="",$F13="",$G13=""),"",IF(AND($F13<=Paramètres!$C$18+6,$G13>=Paramètres!$C$18),1,"")) | R13: =IF(OR($C13="",$F13="",$G13=""),"",IF(AND($F13<=Paramètres!$C$19+6,$G13>=Paramètres!$C$19),1,"")) | S13: =IF(OR($C13="",$F13="",$G13=""),"",IF(AND($F13<=Paramètres!$C$20+6,$G13>=Paramètres!$C$20),1,"")) | T13: =IF(OR($C13="",$F13="",$G13=""),"",IF(AND($F13<=Paramètres!$C$21+6,$G13>=Paramètres!$C$21),1,"")) | U13: =IF(OR($C13="",$F13="",$G13=""),"",IF(AND($F13<=Paramètres!$C$22+6,$G13>=Paramètres!$C$22),1,"")) | V13: =IF(OR($C13="",$F13="",$G13=""),"",IF(AND($F13<=Paramètres!$C$23+6,$G13>=Paramètres!$C$23),1,"")) | W13: =IF(OR($C13="",$F13="",$G13=""),"",IF(AND($F13<=Paramètres!$C$24+6,$G13>=Paramètres!$C$24),1,"")) | X13: =IF(OR($C13="",$F13="",$G13=""),"",IF(AND($F13<=Paramètres!$C$25+6,$G13>=Paramètres!$C$25),1,"")) | Y13: =IF(OR($C13="",$F13="",$G13=""),"",IF(AND($F13<=Paramètres!$C$26+6,$G13>=Paramètres!$C$26),1,"")) | Z13: =IF(OR($C13="",$F13="",$G13=""),"",IF(AND($F13<=Paramètres!$C$27+6,$G13>=Paramètres!$C$27),1,""))
B14: UE2 | C14: Financement & structure du capital | D14: Cours | E14: Moyenne | F14: =Paramètres!$C$5+(7-1)*7 | G14: =Paramètres!$C$5+(8)*7-1 | H14: 0 | I14: =IF(C14="","",IF(H14>=1,"Terminé",IF(AND(G14<>"",G14<TODAY(),H14<1),"En retard",IF(H14>0,"En cours","À faire")))) | J14: =IF(OR(C14="",G14=""),"",G14-TODAY()) | K14: =IF(OR($C14="",$F14="",$G14=""),"",IF(AND($F14<=Paramètres!$C$12+6,$G14>=Paramètres!$C$12),1,"")) | L14: =IF(OR($C14="",$F14="",$G14=""),"",IF(AND($F14<=Paramètres!$C$13+6,$G14>=Paramètres!$C$13),1,"")) | M14: =IF(OR($C14="",$F14="",$G14=""),"",IF(AND($F14<=Paramètres!$C$14+6,$G14>=Paramètres!$C$14),1,"")) | N14: =IF(OR($C14="",$F14="",$G14=""),"",IF(AND($F14<=Paramètres!$C$15+6,$G14>=Paramètres!$C$15),1,"")) | O14: =IF(OR($C14="",$F14="",$G14=""),"",IF(AND($F14<=Paramètres!$C$16+6,$G14>=Paramètres!$C$16),1,"")) | P14: =IF(OR($C14="",$F14="",$G14=""),"",IF(AND($F14<=Paramètres!$C$17+6,$G14>=Paramètres!$C$17),1,"")) | Q14: =IF(OR($C14="",$F14="",$G14=""),"",IF(AND($F14<=Paramètres!$C$18+6,$G14>=Paramètres!$C$18),1,"")) | R14: =IF(OR($C14="",$F14="",$G14=""),"",IF(AND($F14<=Paramètres!$C$19+6,$G14>=Paramètres!$C$19),1,"")) | S14: =IF(OR($C14="",$F14="",$G14=""),"",IF(AND($F14<=Paramètres!$C$20+6,$G14>=Paramètres!$C$20),1,"")) | T14: =IF(OR($C14="",$F14="",$G14=""),"",IF(AND($F14<=Paramètres!$C$21+6,$G14>=Paramètres!$C$21),1,"")) | U14: =IF(OR($C14="",$F14="",$G14=""),"",IF(AND($F14<=Paramètres!$C$22+6,$G14>=Paramètres!$C$22),1,"")) | V14: =IF(OR($C14="",$F14="",$G14=""),"",IF(AND($F14<=Paramètres!$C$23+6,$G14>=Paramètres!$C$23),1,"")) | W14: =IF(OR($C14="",$F14="",$G14=""),"",IF(AND($F14<=Paramètres!$C$24+6,$G14>=Paramètres!$C$24),1,"")) | X14: =IF(OR($C14="",$F14="",$G14=""),"",IF(AND($F14<=Paramètres!$C$25+6,$G14>=Paramètres!$C$25),1,"")) | Y14: =IF(OR($C14="",$F14="",$G14=""),"",IF(AND($F14<=Paramètres!$C$26+6,$G14>=Paramètres!$C$26),1,"")) | Z14: =IF(OR($C14="",$F14="",$G14=""),"",IF(AND($F14<=Paramètres!$C$27+6,$G14>=Paramètres!$C$27),1,""))
B15: UE2 | C15: Ingénierie financière & fusions | D15: Cours | E15: Moyenne | F15: =Paramètres!$C$5+(9-1)*7 | G15: =Paramètres!$C$5+(10)*7-1 | H15: 0 | I15: =IF(C15="","",IF(H15>=1,"Terminé",IF(AND(G15<>"",G15<TODAY(),H15<1),"En retard",IF(H15>0,"En cours","À faire")))) | J15: =IF(OR(C15="",G15=""),"",G15-TODAY()) | K15: =IF(OR($C15="",$F15="",$G15=""),"",IF(AND($F15<=Paramètres!$C$12+6,$G15>=Paramètres!$C$12),1,"")) | L15: =IF(OR($C15="",$F15="",$G15=""),"",IF(AND($F15<=Paramètres!$C$13+6,$G15>=Paramètres!$C$13),1,"")) | M15: =IF(OR($C15="",$F15="",$G15=""),"",IF(AND($F15<=Paramètres!$C$14+6,$G15>=Paramètres!$C$14),1,"")) | N15: =IF(OR($C15="",$F15="",$G15=""),"",IF(AND($F15<=Paramètres!$C$15+6,$G15>=Paramètres!$C$15),1,"")) | O15: =IF(OR($C15="",$F15="",$G15=""),"",IF(AND($F15<=Paramètres!$C$16+6,$G15>=Paramètres!$C$16),1,"")) | P15: =IF(OR($C15="",$F15="",$G15=""),"",IF(AND($F15<=Paramètres!$C$17+6,$G15>=Paramètres!$C$17),1,"")) | Q15: =IF(OR($C15="",$F15="",$G15=""),"",IF(AND($F15<=Paramètres!$C$18+6,$G15>=Paramètres!$C$18),1,"")) | R15: =IF(OR($C15="",$F15="",$G15=""),"",IF(AND($F15<=Paramètres!$C$19+6,$G15>=Paramètres!$C$19),1,"")) | S15: =IF(OR($C15="",$F15="",$G15=""),"",IF(AND($F15<=Paramètres!$C$20+6,$G15>=Paramètres!$C$20),1,"")) | T15: =IF(OR($C15="",$F15="",$G15=""),"",IF(AND($F15<=Paramètres!$C$21+6,$G15>=Paramètres!$C$21),1,"")) | U15: =IF(OR($C15="",$F15="",$G15=""),"",IF(AND($F15<=Paramètres!$C$22+6,$G15>=Paramètres!$C$22),1,"")) | V15: =IF(OR($C15="",$F15="",$G15=""),"",IF(AND($F15<=Paramètres!$C$23+6,$G15>=Paramètres!$C$23),1,"")) | W15: =IF(OR($C15="",$F15="",$G15=""),"",IF(AND($F15<=Paramètres!$C$24+6,$G15>=Paramètres!$C$24),1,"")) | X15: =IF(OR($C15="",$F15="",$G15=""),"",IF(AND($F15<=Paramètres!$C$25+6,$G15>=Paramètres!$C$25),1,"")) | Y15: =IF(OR($C15="",$F15="",$G15=""),"",IF(AND($F15<=Paramètres!$C$26+6,$G15>=Paramètres!$C$26),1,"")) | Z15: =IF(OR($C15="",$F15="",$G15=""),"",IF(AND($F15<=Paramètres!$C$27+6,$G15>=Paramètres!$C$27),1,""))
B16: UE2 | C16: Annales UE2 — sujets blancs | D16: Annales | E16: Haute | F16: =Paramètres!$C$5+(14-1)*7 | G16: =Paramètres!$C$5+(15)*7-1 | H16: 0 | I16: =IF(C16="","",IF(H16>=1,"Terminé",IF(AND(G16<>"",G16<TODAY(),H16<1),"En retard",IF(H16>0,"En cours","À faire")))) | J16: =IF(OR(C16="",G16=""),"",G16-TODAY()) | K16: =IF(OR($C16="",$F16="",$G16=""),"",IF(AND($F16<=Paramètres!$C$12+6,$G16>=Paramètres!$C$12),1,"")) | L16: =IF(OR($C16="",$F16="",$G16=""),"",IF(AND($F16<=Paramètres!$C$13+6,$G16>=Paramètres!$C$13),1,"")) | M16: =IF(OR($C16="",$F16="",$G16=""),"",IF(AND($F16<=Paramètres!$C$14+6,$G16>=Paramètres!$C$14),1,"")) | N16: =IF(OR($C16="",$F16="",$G16=""),"",IF(AND($F16<=Paramètres!$C$15+6,$G16>=Paramètres!$C$15),1,"")) | O16: =IF(OR($C16="",$F16="",$G16=""),"",IF(AND($F16<=Paramètres!$C$16+6,$G16>=Paramètres!$C$16),1,"")) | P16: =IF(OR($C16="",$F16="",$G16=""),"",IF(AND($F16<=Paramètres!$C$17+6,$G16>=Paramètres!$C$17),1,"")) | Q16: =IF(OR($C16="",$F16="",$G16=""),"",IF(AND($F16<=Paramètres!$C$18+6,$G16>=Paramètres!$C$18),1,"")) | R16: =IF(OR($C16="",$F16="",$G16=""),"",IF(AND($F16<=Paramètres!$C$19+6,$G16>=Paramètres!$C$19),1,"")) | S16: =IF(OR($C16="",$F16="",$G16=""),"",IF(AND($F16<=Paramètres!$C$20+6,$G16>=Paramètres!$C$20),1,"")) | T16: =IF(OR($C16="",$F16="",$G16=""),"",IF(AND($F16<=Paramètres!$C$21+6,$G16>=Paramètres!$C$21),1,"")) | U16: =IF(OR($C16="",$F16="",$G16=""),"",IF(AND($F16<=Paramètres!$C$22+6,$G16>=Paramètres!$C$22),1,"")) | V16: =IF(OR($C16="",$F16="",$G16=""),"",IF(AND($F16<=Paramètres!$C$23+6,$G16>=Paramètres!$C$23),1,"")) | W16: =IF(OR($C16="",$F16="",$G16=""),"",IF(AND($F16<=Paramètres!$C$24+6,$G16>=Paramètres!$C$24),1,"")) | X16: =IF(OR($C16="",$F16="",$G16=""),"",IF(AND($F16<=Paramètres!$C$25+6,$G16>=Paramètres!$C$25),1,"")) | Y16: =IF(OR($C16="",$F16="",$G16=""),"",IF(AND($F16<=Paramètres!$C$26+6,$G16>=Paramètres!$C$26),1,"")) | Z16: =IF(OR($C16="",$F16="",$G16=""),"",IF(AND($F16<=Paramètres!$C$27+6,$G16>=Paramètres!$C$27),1,""))
B17: UE3 | C17: Pilotage stratégique & BSC | D17: Cours | E17: Moyenne | F17: =Paramètres!$C$5+(2-1)*7 | G17: =Paramètres!$C$5+(3)*7-1 | H17: 0 | I17: =IF(C17="","",IF(H17>=1,"Terminé",IF(AND(G17<>"",G17<TODAY(),H17<1),"En retard",IF(H17>0,"En cours","À faire")))) | J17: =IF(OR(C17="",G17=""),"",G17-TODAY()) | K17: =IF(OR($C17="",$F17="",$G17=""),"",IF(AND($F17<=Paramètres!$C$12+6,$G17>=Paramètres!$C$12),1,"")) | L17: =IF(OR($C17="",$F17="",$G17=""),"",IF(AND($F17<=Paramètres!$C$13+6,$G17>=Paramètres!$C$13),1,"")) | M17: =IF(OR($C17="",$F17="",$G17=""),"",IF(AND($F17<=Paramètres!$C$14+6,$G17>=Paramètres!$C$14),1,"")) | N17: =IF(OR($C17="",$F17="",$G17=""),"",IF(AND($F17<=Paramètres!$C$15+6,$G17>=Paramètres!$C$15),1,"")) | O17: =IF(OR($C17="",$F17="",$G17=""),"",IF(AND($F17<=Paramètres!$C$16+6,$G17>=Paramètres!$C$16),1,"")) | P17: =IF(OR($C17="",$F17="",$G17=""),"",IF(AND($F17<=Paramètres!$C$17+6,$G17>=Paramètres!$C$17),1,"")) | Q17: =IF(OR($C17="",$F17="",$G17=""),"",IF(AND($F17<=Paramètres!$C$18+6,$G17>=Paramètres!$C$18),1,"")) | R17: =IF(OR($C17="",$F17="",$G17=""),"",IF(AND($F17<=Paramètres!$C$19+6,$G17>=Paramètres!$C$19),1,"")) | S17: =IF(OR($C17="",$F17="",$G17=""),"",IF(AND($F17<=Paramètres!$C$20+6,$G17>=Paramètres!$C$20),1,"")) | T17: =IF(OR($C17="",$F17="",$G17=""),"",IF(AND($F17<=Paramètres!$C$21+6,$G17>=Paramètres!$C$21),1,"")) | U17: =IF(OR($C17="",$F17="",$G17=""),"",IF(AND($F17<=Paramètres!$C$22+6,$G17>=Paramètres!$C$22),1,"")) | V17: =IF(OR($C17="",$F17="",$G17=""),"",IF(AND($F17<=Paramètres!$C$23+6,$G17>=Paramètres!$C$23),1,"")) | W17: =IF(OR($C17="",$F17="",$G17=""),"",IF(AND($F17<=Paramètres!$C$24+6,$G17>=Paramètres!$C$24),1,"")) | X17: =IF(OR($C17="",$F17="",$G17=""),"",IF(AND($F17<=Paramètres!$C$25+6,$G17>=Paramètres!$C$25),1,"")) | Y17: =IF(OR($C17="",$F17="",$G17=""),"",IF(AND($F17<=Paramètres!$C$26+6,$G17>=Paramètres!$C$26),1,"")) | Z17: =IF(OR($C17="",$F17="",$G17=""),"",IF(AND($F17<=Paramètres!$C$27+6,$G17>=Paramètres!$C$27),1,""))
B18: UE3 | C18: Contrôle de gestion — coûts & budgets | D18: Exercices | E18: Haute | F18: =Paramètres!$C$5+(4-1)*7 | G18: =Paramètres!$C$5+(6)*7-1 | H18: 0 | I18: =IF(C18="","",IF(H18>=1,"Terminé",IF(AND(G18<>"",G18<TODAY(),H18<1),"En retard",IF(H18>0,"En cours","À faire")))) | J18: =IF(OR(C18="",G18=""),"",G18-TODAY()) | K18: =IF(OR($C18="",$F18="",$G18=""),"",IF(AND($F18<=Paramètres!$C$12+6,$G18>=Paramètres!$C$12),1,"")) | L18: =IF(OR($C18="",$F18="",$G18=""),"",IF(AND($F18<=Paramètres!$C$13+6,$G18>=Paramètres!$C$13),1,"")) | M18: =IF(OR($C18="",$F18="",$G18=""),"",IF(AND($F18<=Paramètres!$C$14+6,$G18>=Paramètres!$C$14),1,"")) | N18: =IF(OR($C18="",$F18="",$G18=""),"",IF(AND($F18<=Paramètres!$C$15+6,$G18>=Paramètres!$C$15),1,"")) | O18: =IF(OR($C18="",$F18="",$G18=""),"",IF(AND($F18<=Paramètres!$C$16+6,$G18>=Paramètres!$C$16),1,"")) | P18: =IF(OR($C18="",$F18="",$G18=""),"",IF(AND($F18<=Paramètres!$C$17+6,$G18>=Paramètres!$C$17),1,"")) | Q18: =IF(OR($C18="",$F18="",$G18=""),"",IF(AND($F18<=Paramètres!$C$18+6,$G18>=Paramètres!$C$18),1,"")) | R18: =IF(OR($C18="",$F18="",$G18=""),"",IF(AND($F18<=Paramètres!$C$19+6,$G18>=Paramètres!$C$19),1,"")) | S18: =IF(OR($C18="",$F18="",$G18=""),"",IF(AND($F18<=Paramètres!$C$20+6,$G18>=Paramètres!$C$20),1,"")) | T18: =IF(OR($C18="",$F18="",$G18=""),"",IF(AND($F18<=Paramètres!$C$21+6,$G18>=Paramètres!$C$21),1,"")) | U18: =IF(OR($C18="",$F18="",$G18=""),"",IF(AND($F18<=Paramètres!$C$22+6,$G18>=Paramètres!$C$22),1,"")) | V18: =IF(OR($C18="",$F18="",$G18=""),"",IF(AND($F18<=Paramètres!$C$23+6,$G18>=Paramètres!$C$23),1,"")) | W18: =IF(OR($C18="",$F18="",$G18=""),"",IF(AND($F18<=Paramètres!$C$24+6,$G18>=Paramètres!$C$24),1,"")) | X18: =IF(OR($C18="",$F18="",$G18=""),"",IF(AND($F18<=Paramètres!$C$25+6,$G18>=Paramètres!$C$25),1,"")) | Y18: =IF(OR($C18="",$F18="",$G18=""),"",IF(AND($F18<=Paramètres!$C$26+6,$G18>=Paramètres!$C$26),1,"")) | Z18: =IF(OR($C18="",$F18="",$G18=""),"",IF(AND($F18<=Paramètres!$C$27+6,$G18>=Paramètres!$C$27),1,""))
B19: UE3 | C19: Gestion de projet & organisation | D19: Cours | E19: Basse | F19: =Paramètres!$C$5+(8-1)*7 | G19: =Paramètres!$C$5+(9)*7-1 | H19: 0 | I19: =IF(C19="","",IF(H19>=1,"Terminé",IF(AND(G19<>"",G19<TODAY(),H19<1),"En retard",IF(H19>0,"En cours","À faire")))) | J19: =IF(OR(C19="",G19=""),"",G19-TODAY()) | K19: =IF(OR($C19="",$F19="",$G19=""),"",IF(AND($F19<=Paramètres!$C$12+6,$G19>=Paramètres!$C$12),1,"")) | L19: =IF(OR($C19="",$F19="",$G19=""),"",IF(AND($F19<=Paramètres!$C$13+6,$G19>=Paramètres!$C$13),1,"")) | M19: =IF(OR($C19="",$F19="",$G19=""),"",IF(AND($F19<=Paramètres!$C$14+6,$G19>=Paramètres!$C$14),1,"")) | N19: =IF(OR($C19="",$F19="",$G19=""),"",IF(AND($F19<=Paramètres!$C$15+6,$G19>=Paramètres!$C$15),1,"")) | O19: =IF(OR($C19="",$F19="",$G19=""),"",IF(AND($F19<=Paramètres!$C$16+6,$G19>=Paramètres!$C$16),1,"")) | P19: =IF(OR($C19="",$F19="",$G19=""),"",IF(AND($F19<=Paramètres!$C$17+6,$G19>=Paramètres!$C$17),1,"")) | Q19: =IF(OR($C19="",$F19="",$G19=""),"",IF(AND($F19<=Paramètres!$C$18+6,$G19>=Paramètres!$C$18),1,"")) | R19: =IF(OR($C19="",$F19="",$G19=""),"",IF(AND($F19<=Paramètres!$C$19+6,$G19>=Paramètres!$C$19),1,"")) | S19: =IF(OR($C19="",$F19="",$G19=""),"",IF(AND($F19<=Paramètres!$C$20+6,$G19>=Paramètres!$C$20),1,"")) | T19: =IF(OR($C19="",$F19="",$G19=""),"",IF(AND($F19<=Paramètres!$C$21+6,$G19>=Paramètres!$C$21),1,"")) | U19: =IF(OR($C19="",$F19="",$G19=""),"",IF(AND($F19<=Paramètres!$C$22+6,$G19>=Paramètres!$C$22),1,"")) | V19: =IF(OR($C19="",$F19="",$G19=""),"",IF(AND($F19<=Paramètres!$C$23+6,$G19>=Paramètres!$C$23),1,"")) | W19: =IF(OR($C19="",$F19="",$G19=""),"",IF(AND($F19<=Paramètres!$C$24+6,$G19>=Paramètres!$C$24),1,"")) | X19: =IF(OR($C19="",$F19="",$G19=""),"",IF(AND($F19<=Paramètres!$C$25+6,$G19>=Paramètres!$C$25),1,"")) | Y19: =IF(OR($C19="",$F19="",$G19=""),"",IF(AND($F19<=Paramètres!$C$26+6,$G19>=Paramètres!$C$26),1,"")) | Z19: =IF(OR($C19="",$F19="",$G19=""),"",IF(AND($F19<=Paramètres!$C$27+6,$G19>=Paramètres!$C$27),1,""))
B20: UE3 | C20: Annales UE3 — sujets blancs | D20: Annales | E20: Moyenne | F20: =Paramètres!$C$5+(13-1)*7 | G20: =Paramètres!$C$5+(14)*7-1 | H20: 0 | I20: =IF(C20="","",IF(H20>=1,"Terminé",IF(AND(G20<>"",G20<TODAY(),H20<1),"En retard",IF(H20>0,"En cours","À faire")))) | J20: =IF(OR(C20="",G20=""),"",G20-TODAY()) | K20: =IF(OR($C20="",$F20="",$G20=""),"",IF(AND($F20<=Paramètres!$C$12+6,$G20>=Paramètres!$C$12),1,"")) | L20: =IF(OR($C20="",$F20="",$G20=""),"",IF(AND($F20<=Paramètres!$C$13+6,$G20>=Paramètres!$C$13),1,"")) | M20: =IF(OR($C20="",$F20="",$G20=""),"",IF(AND($F20<=Paramètres!$C$14+6,$G20>=Paramètres!$C$14),1,"")) | N20: =IF(OR($C20="",$F20="",$G20=""),"",IF(AND($F20<=Paramètres!$C$15+6,$G20>=Paramètres!$C$15),1,"")) | O20: =IF(OR($C20="",$F20="",$G20=""),"",IF(AND($F20<=Paramètres!$C$16+6,$G20>=Paramètres!$C$16),1,"")) | P20: =IF(OR($C20="",$F20="",$G20=""),"",IF(AND($F20<=Paramètres!$C$17+6,$G20>=Paramètres!$C$17),1,"")) | Q20: =IF(OR($C20="",$F20="",$G20=""),"",IF(AND($F20<=Paramètres!$C$18+6,$G20>=Paramètres!$C$18),1,"")) | R20: =IF(OR($C20="",$F20="",$G20=""),"",IF(AND($F20<=Paramètres!$C$19+6,$G20>=Paramètres!$C$19),1,"")) | S20: =IF(OR($C20="",$F20="",$G20=""),"",IF(AND($F20<=Paramètres!$C$20+6,$G20>=Paramètres!$C$20),1,"")) | T20: =IF(OR($C20="",$F20="",$G20=""),"",IF(AND($F20<=Paramètres!$C$21+6,$G20>=Paramètres!$C$21),1,"")) | U20: =IF(OR($C20="",$F20="",$G20=""),"",IF(AND($F20<=Paramètres!$C$22+6,$G20>=Paramètres!$C$22),1,"")) | V20: =IF(OR($C20="",$F20="",$G20=""),"",IF(AND($F20<=Paramètres!$C$23+6,$G20>=Paramètres!$C$23),1,"")) | W20: =IF(OR($C20="",$F20="",$G20=""),"",IF(AND($F20<=Paramètres!$C$24+6,$G20>=Paramètres!$C$24),1,"")) | X20: =IF(OR($C20="",$F20="",$G20=""),"",IF(AND($F20<=Paramètres!$C$25+6,$G20>=Paramètres!$C$25),1,"")) | Y20: =IF(OR($C20="",$F20="",$G20=""),"",IF(AND($F20<=Paramètres!$C$26+6,$G20>=Paramètres!$C$26),1,"")) | Z20: =IF(OR($C20="",$F20="",$G20=""),"",IF(AND($F20<=Paramètres!$C$27+6,$G20>=Paramètres!$C$27),1,""))
B21: UE4 | C21: Consolidation — pourcentages & méthodes | D21: Cours | E21: Haute | F21: =Paramètres!$C$5+(1-1)*7 | G21: =Paramètres!$C$5+(3)*7-1 | H21: 0 | I21: =IF(C21="","",IF(H21>=1,"Terminé",IF(AND(G21<>"",G21<TODAY(),H21<1),"En retard",IF(H21>0,"En cours","À faire")))) | J21: =IF(OR(C21="",G21=""),"",G21-TODAY()) | K21: =IF(OR($C21="",$F21="",$G21=""),"",IF(AND($F21<=Paramètres!$C$12+6,$G21>=Paramètres!$C$12),1,"")) | L21: =IF(OR($C21="",$F21="",$G21=""),"",IF(AND($F21<=Paramètres!$C$13+6,$G21>=Paramètres!$C$13),1,"")) | M21: =IF(OR($C21="",$F21="",$G21=""),"",IF(AND($F21<=Paramètres!$C$14+6,$G21>=Paramètres!$C$14),1,"")) | N21: =IF(OR($C21="",$F21="",$G21=""),"",IF(AND($F21<=Paramètres!$C$15+6,$G21>=Paramètres!$C$15),1,"")) | O21: =IF(OR($C21="",$F21="",$G21=""),"",IF(AND($F21<=Paramètres!$C$16+6,$G21>=Paramètres!$C$16),1,"")) | P21: =IF(OR($C21="",$F21="",$G21=""),"",IF(AND($F21<=Paramètres!$C$17+6,$G21>=Paramètres!$C$17),1,"")) | Q21: =IF(OR($C21="",$F21="",$G21=""),"",IF(AND($F21<=Paramètres!$C$18+6,$G21>=Paramètres!$C$18),1,"")) | R21: =IF(OR($C21="",$F21="",$G21=""),"",IF(AND($F21<=Paramètres!$C$19+6,$G21>=Paramètres!$C$19),1,"")) | S21: =IF(OR($C21="",$F21="",$G21=""),"",IF(AND($F21<=Paramètres!$C$20+6,$G21>=Paramètres!$C$20),1,"")) | T21: =IF(OR($C21="",$F21="",$G21=""),"",IF(AND($F21<=Paramètres!$C$21+6,$G21>=Paramètres!$C$21),1,"")) | U21: =IF(OR($C21="",$F21="",$G21=""),"",IF(AND($F21<=Paramètres!$C$22+6,$G21>=Paramètres!$C$22),1,"")) | V21: =IF(OR($C21="",$F21="",$G21=""),"",IF(AND($F21<=Paramètres!$C$23+6,$G21>=Paramètres!$C$23),1,"")) | W21: =IF(OR($C21="",$F21="",$G21=""),"",IF(AND($F21<=Paramètres!$C$24+6,$G21>=Paramètres!$C$24),1,"")) | X21: =IF(OR($C21="",$F21="",$G21=""),"",IF(AND($F21<=Paramètres!$C$25+6,$G21>=Paramètres!$C$25),1,"")) | Y21: =IF(OR($C21="",$F21="",$G21=""),"",IF(AND($F21<=Paramètres!$C$26+6,$G21>=Paramètres!$C$26),1,"")) | Z21: =IF(OR($C21="",$F21="",$G21=""),"",IF(AND($F21<=Paramètres!$C$27+6,$G21>=Paramètres!$C$27),1,""))
B22: UE4 | C22: Consolidation — écarts d'acquisition & variation | D22: Exercices | E22: Haute | F22: =Paramètres!$C$5+(4-1)*7 | G22: =Paramètres!$C$5+(5)*7-1 | H22: 0 | I22: =IF(C22="","",IF(H22>=1,"Terminé",IF(AND(G22<>"",G22<TODAY(),H22<1),"En retard",IF(H22>0,"En cours","À faire")))) | J22: =IF(OR(C22="",G22=""),"",G22-TODAY()) | K22: =IF(OR($C22="",$F22="",$G22=""),"",IF(AND($F22<=Paramètres!$C$12+6,$G22>=Paramètres!$C$12),1,"")) | L22: =IF(OR($C22="",$F22="",$G22=""),"",IF(AND($F22<=Paramètres!$C$13+6,$G22>=Paramètres!$C$13),1,"")) | M22: =IF(OR($C22="",$F22="",$G22=""),"",IF(AND($F22<=Paramètres!$C$14+6,$G22>=Paramètres!$C$14),1,"")) | N22: =IF(OR($C22="",$F22="",$G22=""),"",IF(AND($F22<=Paramètres!$C$15+6,$G22>=Paramètres!$C$15),1,"")) | O22: =IF(OR($C22="",$F22="",$G22=""),"",IF(AND($F22<=Paramètres!$C$16+6,$G22>=Paramètres!$C$16),1,"")) | P22: =IF(OR($C22="",$F22="",$G22=""),"",IF(AND($F22<=Paramètres!$C$17+6,$G22>=Paramètres!$C$17),1,"")) | Q22: =IF(OR($C22="",$F22="",$G22=""),"",IF(AND($F22<=Paramètres!$C$18+6,$G22>=Paramètres!$C$18),1,"")) | R22: =IF(OR($C22="",$F22="",$G22=""),"",IF(AND($F22<=Paramètres!$C$19+6,$G22>=Paramètres!$C$19),1,"")) | S22: =IF(OR($C22="",$F22="",$G22=""),"",IF(AND($F22<=Paramètres!$C$20+6,$G22>=Paramètres!$C$20),1,"")) | T22: =IF(OR($C22="",$F22="",$G22=""),"",IF(AND($F22<=Paramètres!$C$21+6,$G22>=Paramètres!$C$21),1,"")) | U22: =IF(OR($C22="",$F22="",$G22=""),"",IF(AND($F22<=Paramètres!$C$22+6,$G22>=Paramètres!$C$22),1,"")) | V22: =IF(OR($C22="",$F22="",$G22=""),"",IF(AND($F22<=Paramètres!$C$23+6,$G22>=Paramètres!$C$23),1,"")) | W22: =IF(OR($C22="",$F22="",$G22=""),"",IF(AND($F22<=Paramètres!$C$24+6,$G22>=Paramètres!$C$24),1,"")) | X22: =IF(OR($C22="",$F22="",$G22=""),"",IF(AND($F22<=Paramètres!$C$25+6,$G22>=Paramètres!$C$25),1,"")) | Y22: =IF(OR($C22="",$F22="",$G22=""),"",IF(AND($F22<=Paramètres!$C$26+6,$G22>=Paramètres!$C$26),1,"")) | Z22: =IF(OR($C22="",$F22="",$G22=""),"",IF(AND($F22<=Paramètres!$C$27+6,$G22>=Paramètres!$C$27),1,""))
B23: UE4 | C23: Normes IFRS — immobilisations & instruments | D23: Cours | E23: Haute | F23: =Paramètres!$C$5+(6-1)*7 | G23: =Paramètres!$C$5+(8)*7-1 | H23: 0 | I23: =IF(C23="","",IF(H23>=1,"Terminé",IF(AND(G23<>"",G23<TODAY(),H23<1),"En retard",IF(H23>0,"En cours","À faire")))) | J23: =IF(OR(C23="",G23=""),"",G23-TODAY()) | K23: =IF(OR($C23="",$F23="",$G23=""),"",IF(AND($F23<=Paramètres!$C$12+6,$G23>=Paramètres!$C$12),1,"")) | L23: =IF(OR($C23="",$F23="",$G23=""),"",IF(AND($F23<=Paramètres!$C$13+6,$G23>=Paramètres!$C$13),1,"")) | M23: =IF(OR($C23="",$F23="",$G23=""),"",IF(AND($F23<=Paramètres!$C$14+6,$G23>=Paramètres!$C$14),1,"")) | N23: =IF(OR($C23="",$F23="",$G23=""),"",IF(AND($F23<=Paramètres!$C$15+6,$G23>=Paramètres!$C$15),1,"")) | O23: =IF(OR($C23="",$F23="",$G23=""),"",IF(AND($F23<=Paramètres!$C$16+6,$G23>=Paramètres!$C$16),1,"")) | P23: =IF(OR($C23="",$F23="",$G23=""),"",IF(AND($F23<=Paramètres!$C$17+6,$G23>=Paramètres!$C$17),1,"")) | Q23: =IF(OR($C23="",$F23="",$G23=""),"",IF(AND($F23<=Paramètres!$C$18+6,$G23>=Paramètres!$C$18),1,"")) | R23: =IF(OR($C23="",$F23="",$G23=""),"",IF(AND($F23<=Paramètres!$C$19+6,$G23>=Paramètres!$C$19),1,"")) | S23: =IF(OR($C23="",$F23="",$G23=""),"",IF(AND($F23<=Paramètres!$C$20+6,$G23>=Paramètres!$C$20),1,"")) | T23: =IF(OR($C23="",$F23="",$G23=""),"",IF(AND($F23<=Paramètres!$C$21+6,$G23>=Paramètres!$C$21),1,"")) | U23: =IF(OR($C23="",$F23="",$G23=""),"",IF(AND($F23<=Paramètres!$C$22+6,$G23>=Paramètres!$C$22),1,"")) | V23: =IF(OR($C23="",$F23="",$G23=""),"",IF(AND($F23<=Paramètres!$C$23+6,$G23>=Paramètres!$C$23),1,"")) | W23: =IF(OR($C23="",$F23="",$G23=""),"",IF(AND($F23<=Paramètres!$C$24+6,$G23>=Paramètres!$C$24),1,"")) | X23: =IF(OR($C23="",$F23="",$G23=""),"",IF(AND($F23<=Paramètres!$C$25+6,$G23>=Paramètres!$C$25),1,"")) | Y23: =IF(OR($C23="",$F23="",$G23=""),"",IF(AND($F23<=Paramètres!$C$26+6,$G23>=Paramètres!$C$26),1,"")) | Z23: =IF(OR($C23="",$F23="",$G23=""),"",IF(AND($F23<=Paramètres!$C$27+6,$G23>=Paramètres!$C$27),1,""))
B24: UE4 | C24: Audit — démarche & risques | D24: Cours | E24: Moyenne | F24: =Paramètres!$C$5+(9-1)*7 | G24: =Paramètres!$C$5+(10)*7-1 | H24: 0 | I24: =IF(C24="","",IF(H24>=1,"Terminé",IF(AND(G24<>"",G24<TODAY(),H24<1),"En retard",IF(H24>0,"En cours","À faire")))) | J24: =IF(OR(C24="",G24=""),"",G24-TODAY()) | K24: =IF(OR($C24="",$F24="",$G24=""),"",IF(AND($F24<=Paramètres!$C$12+6,$G24>=Paramètres!$C$12),1,"")) | L24: =IF(OR($C24="",$F24="",$G24=""),"",IF(AND($F24<=Paramètres!$C$13+6,$G24>=Paramètres!$C$13),1,"")) | M24: =IF(OR($C24="",$F24="",$G24=""),"",IF(AND($F24<=Paramètres!$C$14+6,$G24>=Paramètres!$C$14),1,"")) | N24: =IF(OR($C24="",$F24="",$G24=""),"",IF(AND($F24<=Paramètres!$C$15+6,$G24>=Paramètres!$C$15),1,"")) | O24: =IF(OR($C24="",$F24="",$G24=""),"",IF(AND($F24<=Paramètres!$C$16+6,$G24>=Paramètres!$C$16),1,"")) | P24: =IF(OR($C24="",$F24="",$G24=""),"",IF(AND($F24<=Paramètres!$C$17+6,$G24>=Paramètres!$C$17),1,"")) | Q24: =IF(OR($C24="",$F24="",$G24=""),"",IF(AND($F24<=Paramètres!$C$18+6,$G24>=Paramètres!$C$18),1,"")) | R24: =IF(OR($C24="",$F24="",$G24=""),"",IF(AND($F24<=Paramètres!$C$19+6,$G24>=Paramètres!$C$19),1,"")) | S24: =IF(OR($C24="",$F24="",$G24=""),"",IF(AND($F24<=Paramètres!$C$20+6,$G24>=Paramètres!$C$20),1,"")) | T24: =IF(OR($C24="",$F24="",$G24=""),"",IF(AND($F24<=Paramètres!$C$21+6,$G24>=Paramètres!$C$21),1,"")) | U24: =IF(OR($C24="",$F24="",$G24=""),"",IF(AND($F24<=Paramètres!$C$22+6,$G24>=Paramètres!$C$22),1,"")) | V24: =IF(OR($C24="",$F24="",$G24=""),"",IF(AND($F24<=Paramètres!$C$23+6,$G24>=Paramètres!$C$23),1,"")) | W24: =IF(OR($C24="",$F24="",$G24=""),"",IF(AND($F24<=Paramètres!$C$24+6,$G24>=Paramètres!$C$24),1,"")) | X24: =IF(OR($C24="",$F24="",$G24=""),"",IF(AND($F24<=Paramètres!$C$25+6,$G24>=Paramètres!$C$25),1,"")) | Y24: =IF(OR($C24="",$F24="",$G24=""),"",IF(AND($F24<=Paramètres!$C$26+6,$G24>=Paramètres!$C$26),1,"")) | Z24: =IF(OR($C24="",$F24="",$G24=""),"",IF(AND($F24<=Paramètres!$C$27+6,$G24>=Paramètres!$C$27),1,""))
B25: UE4 | C25: Annales UE4 — sujets blancs | D25: Annales | E25: Haute | F25: =Paramètres!$C$5+(14-1)*7 | G25: =Paramètres!$C$5+(15)*7-1 | H25: 0 | I25: =IF(C25="","",IF(H25>=1,"Terminé",IF(AND(G25<>"",G25<TODAY(),H25<1),"En retard",IF(H25>0,"En cours","À faire")))) | J25: =IF(OR(C25="",G25=""),"",G25-TODAY()) | K25: =IF(OR($C25="",$F25="",$G25=""),"",IF(AND($F25<=Paramètres!$C$12+6,$G25>=Paramètres!$C$12),1,"")) | L25: =IF(OR($C25="",$F25="",$G25=""),"",IF(AND($F25<=Paramètres!$C$13+6,$G25>=Paramètres!$C$13),1,"")) | M25: =IF(OR($C25="",$F25="",$G25=""),"",IF(AND($F25<=Paramètres!$C$14+6,$G25>=Paramètres!$C$14),1,"")) | N25: =IF(OR($C25="",$F25="",$G25=""),"",IF(AND($F25<=Paramètres!$C$15+6,$G25>=Paramètres!$C$15),1,"")) | O25: =IF(OR($C25="",$F25="",$G25=""),"",IF(AND($F25<=Paramètres!$C$16+6,$G25>=Paramètres!$C$16),1,"")) | P25: =IF(OR($C25="",$F25="",$G25=""),"",IF(AND($F25<=Paramètres!$C$17+6,$G25>=Paramètres!$C$17),1,"")) | Q25: =IF(OR($C25="",$F25="",$G25=""),"",IF(AND($F25<=Paramètres!$C$18+6,$G25>=Paramètres!$C$18),1,"")) | R25: =IF(OR($C25="",$F25="",$G25=""),"",IF(AND($F25<=Paramètres!$C$19+6,$G25>=Paramètres!$C$19),1,"")) | S25: =IF(OR($C25="",$F25="",$G25=""),"",IF(AND($F25<=Paramètres!$C$20+6,$G25>=Paramètres!$C$20),1,"")) | T25: =IF(OR($C25="",$F25="",$G25=""),"",IF(AND($F25<=Paramètres!$C$21+6,$G25>=Paramètres!$C$21),1,"")) | U25: =IF(OR($C25="",$F25="",$G25=""),"",IF(AND($F25<=Paramètres!$C$22+6,$G25>=Paramètres!$C$22),1,"")) | V25: =IF(OR($C25="",$F25="",$G25=""),"",IF(AND($F25<=Paramètres!$C$23+6,$G25>=Paramètres!$C$23),1,"")) | W25: =IF(OR($C25="",$F25="",$G25=""),"",IF(AND($F25<=Paramètres!$C$24+6,$G25>=Paramètres!$C$24),1,"")) | X25: =IF(OR($C25="",$F25="",$G25=""),"",IF(AND($F25<=Paramètres!$C$25+6,$G25>=Paramètres!$C$25),1,"")) | Y25: =IF(OR($C25="",$F25="",$G25=""),"",IF(AND($F25<=Paramètres!$C$26+6,$G25>=Paramètres!$C$26),1,"")) | Z25: =IF(OR($C25="",$F25="",$G25=""),"",IF(AND($F25<=Paramètres!$C$27+6,$G25>=Paramètres!$C$27),1,""))
B26: UE5 | C26: Systèmes d'information & gouvernance SI | D26: Cours | E26: Basse | F26: =Paramètres!$C$5+(6-1)*7 | G26: =Paramètres!$C$5+(7)*7-1 | H26: 0 | I26: =IF(C26="","",IF(H26>=1,"Terminé",IF(AND(G26<>"",G26<TODAY(),H26<1),"En retard",IF(H26>0,"En cours","À faire")))) | J26: =IF(OR(C26="",G26=""),"",G26-TODAY()) | K26: =IF(OR($C26="",$F26="",$G26=""),"",IF(AND($F26<=Paramètres!$C$12+6,$G26>=Paramètres!$C$12),1,"")) | L26: =IF(OR($C26="",$F26="",$G26=""),"",IF(AND($F26<=Paramètres!$C$13+6,$G26>=Paramètres!$C$13),1,"")) | M26: =IF(OR($C26="",$F26="",$G26=""),"",IF(AND($F26<=Paramètres!$C$14+6,$G26>=Paramètres!$C$14),1,"")) | N26: =IF(OR($C26="",$F26="",$G26=""),"",IF(AND($F26<=Paramètres!$C$15+6,$G26>=Paramètres!$C$15),1,"")) | O26: =IF(OR($C26="",$F26="",$G26=""),"",IF(AND($F26<=Paramètres!$C$16+6,$G26>=Paramètres!$C$16),1,"")) | P26: =IF(OR($C26="",$F26="",$G26=""),"",IF(AND($F26<=Paramètres!$C$17+6,$G26>=Paramètres!$C$17),1,"")) | Q26: =IF(OR($C26="",$F26="",$G26=""),"",IF(AND($F26<=Paramètres!$C$18+6,$G26>=Paramètres!$C$18),1,"")) | R26: =IF(OR($C26="",$F26="",$G26=""),"",IF(AND($F26<=Paramètres!$C$19+6,$G26>=Paramètres!$C$19),1,"")) | S26: =IF(OR($C26="",$F26="",$G26=""),"",IF(AND($F26<=Paramètres!$C$20+6,$G26>=Paramètres!$C$20),1,"")) | T26: =IF(OR($C26="",$F26="",$G26=""),"",IF(AND($F26<=Paramètres!$C$21+6,$G26>=Paramètres!$C$21),1,"")) | U26: =IF(OR($C26="",$F26="",$G26=""),"",IF(AND($F26<=Paramètres!$C$22+6,$G26>=Paramètres!$C$22),1,"")) | V26: =IF(OR($C26="",$F26="",$G26=""),"",IF(AND($F26<=Paramètres!$C$23+6,$G26>=Paramètres!$C$23),1,"")) | W26: =IF(OR($C26="",$F26="",$G26=""),"",IF(AND($F26<=Paramètres!$C$24+6,$G26>=Paramètres!$C$24),1,"")) | X26: =IF(OR($C26="",$F26="",$G26=""),"",IF(AND($F26<=Paramètres!$C$25+6,$G26>=Paramètres!$C$25),1,"")) | Y26: =IF(OR($C26="",$F26="",$G26=""),"",IF(AND($F26<=Paramètres!$C$26+6,$G26>=Paramètres!$C$26),1,"")) | Z26: =IF(OR($C26="",$F26="",$G26=""),"",IF(AND($F26<=Paramètres!$C$27+6,$G26>=Paramètres!$C$27),1,""))
B27: UE5 | C27: Sécurité, ERP & transformation digitale | D27: Fiches | E27: Basse | F27: =Paramètres!$C$5+(10-1)*7 | G27: =Paramètres!$C$5+(11)*7-1 | H27: 0 | I27: =IF(C27="","",IF(H27>=1,"Terminé",IF(AND(G27<>"",G27<TODAY(),H27<1),"En retard",IF(H27>0,"En cours","À faire")))) | J27: =IF(OR(C27="",G27=""),"",G27-TODAY()) | K27: =IF(OR($C27="",$F27="",$G27=""),"",IF(AND($F27<=Paramètres!$C$12+6,$G27>=Paramètres!$C$12),1,"")) | L27: =IF(OR($C27="",$F27="",$G27=""),"",IF(AND($F27<=Paramètres!$C$13+6,$G27>=Paramètres!$C$13),1,"")) | M27: =IF(OR($C27="",$F27="",$G27=""),"",IF(AND($F27<=Paramètres!$C$14+6,$G27>=Paramètres!$C$14),1,"")) | N27: =IF(OR($C27="",$F27="",$G27=""),"",IF(AND($F27<=Paramètres!$C$15+6,$G27>=Paramètres!$C$15),1,"")) | O27: =IF(OR($C27="",$F27="",$G27=""),"",IF(AND($F27<=Paramètres!$C$16+6,$G27>=Paramètres!$C$16),1,"")) | P27: =IF(OR($C27="",$F27="",$G27=""),"",IF(AND($F27<=Paramètres!$C$17+6,$G27>=Paramètres!$C$17),1,"")) | Q27: =IF(OR($C27="",$F27="",$G27=""),"",IF(AND($F27<=Paramètres!$C$18+6,$G27>=Paramètres!$C$18),1,"")) | R27: =IF(OR($C27="",$F27="",$G27=""),"",IF(AND($F27<=Paramètres!$C$19+6,$G27>=Paramètres!$C$19),1,"")) | S27: =IF(OR($C27="",$F27="",$G27=""),"",IF(AND($F27<=Paramètres!$C$20+6,$G27>=Paramètres!$C$20),1,"")) | T27: =IF(OR($C27="",$F27="",$G27=""),"",IF(AND($F27<=Paramètres!$C$21+6,$G27>=Paramètres!$C$21),1,"")) | U27: =IF(OR($C27="",$F27="",$G27=""),"",IF(AND($F27<=Paramètres!$C$22+6,$G27>=Paramètres!$C$22),1,"")) | V27: =IF(OR($C27="",$F27="",$G27=""),"",IF(AND($F27<=Paramètres!$C$23+6,$G27>=Paramètres!$C$23),1,"")) | W27: =IF(OR($C27="",$F27="",$G27=""),"",IF(AND($F27<=Paramètres!$C$24+6,$G27>=Paramètres!$C$24),1,"")) | X27: =IF(OR($C27="",$F27="",$G27=""),"",IF(AND($F27<=Paramètres!$C$25+6,$G27>=Paramètres!$C$25),1,"")) | Y27: =IF(OR($C27="",$F27="",$G27=""),"",IF(AND($F27<=Paramètres!$C$26+6,$G27>=Paramètres!$C$26),1,"")) | Z27: =IF(OR($C27="",$F27="",$G27=""),"",IF(AND($F27<=Paramètres!$C$27+6,$G27>=Paramètres!$C$27),1,""))
B28: UE6 | C28: Vocabulaire finance & audit | D28: Fiches | E28: Moyenne | F28: =Paramètres!$C$5+(2-1)*7 | G28: =Paramètres!$C$5+(12)*7-1 | H28: 0 | I28: =IF(C28="","",IF(H28>=1,"Terminé",IF(AND(G28<>"",G28<TODAY(),H28<1),"En retard",IF(H28>0,"En cours","À faire")))) | J28: =IF(OR(C28="",G28=""),"",G28-TODAY()) | K28: =IF(OR($C28="",$F28="",$G28=""),"",IF(AND($F28<=Paramètres!$C$12+6,$G28>=Paramètres!$C$12),1,"")) | L28: =IF(OR($C28="",$F28="",$G28=""),"",IF(AND($F28<=Paramètres!$C$13+6,$G28>=Paramètres!$C$13),1,"")) | M28: =IF(OR($C28="",$F28="",$G28=""),"",IF(AND($F28<=Paramètres!$C$14+6,$G28>=Paramètres!$C$14),1,"")) | N28: =IF(OR($C28="",$F28="",$G28=""),"",IF(AND($F28<=Paramètres!$C$15+6,$G28>=Paramètres!$C$15),1,"")) | O28: =IF(OR($C28="",$F28="",$G28=""),"",IF(AND($F28<=Paramètres!$C$16+6,$G28>=Paramètres!$C$16),1,"")) | P28: =IF(OR($C28="",$F28="",$G28=""),"",IF(AND($F28<=Paramètres!$C$17+6,$G28>=Paramètres!$C$17),1,"")) | Q28: =IF(OR($C28="",$F28="",$G28=""),"",IF(AND($F28<=Paramètres!$C$18+6,$G28>=Paramètres!$C$18),1,"")) | R28: =IF(OR($C28="",$F28="",$G28=""),"",IF(AND($F28<=Paramètres!$C$19+6,$G28>=Paramètres!$C$19),1,"")) | S28: =IF(OR($C28="",$F28="",$G28=""),"",IF(AND($F28<=Paramètres!$C$20+6,$G28>=Paramètres!$C$20),1,"")) | T28: =IF(OR($C28="",$F28="",$G28=""),"",IF(AND($F28<=Paramètres!$C$21+6,$G28>=Paramètres!$C$21),1,"")) | U28: =IF(OR($C28="",$F28="",$G28=""),"",IF(AND($F28<=Paramètres!$C$22+6,$G28>=Paramètres!$C$22),1,"")) | V28: =IF(OR($C28="",$F28="",$G28=""),"",IF(AND($F28<=Paramètres!$C$23+6,$G28>=Paramètres!$C$23),1,"")) | W28: =IF(OR($C28="",$F28="",$G28=""),"",IF(AND($F28<=Paramètres!$C$24+6,$G28>=Paramètres!$C$24),1,"")) | X28: =IF(OR($C28="",$F28="",$G28=""),"",IF(AND($F28<=Paramètres!$C$25+6,$G28>=Paramètres!$C$25),1,"")) | Y28: =IF(OR($C28="",$F28="",$G28=""),"",IF(AND($F28<=Paramètres!$C$26+6,$G28>=Paramètres!$C$26),1,"")) | Z28: =IF(OR($C28="",$F28="",$G28=""),"",IF(AND($F28<=Paramètres!$C$27+6,$G28>=Paramètres!$C$27),1,""))
B29: UE6 | C29: Entraînement compréhension écrite | D29: Exercices | E29: Moyenne | F29: =Paramètres!$C$5+(3-1)*7 | G29: =Paramètres!$C$5+(13)*7-1 | H29: 0 | I29: =IF(C29="","",IF(H29>=1,"Terminé",IF(AND(G29<>"",G29<TODAY(),H29<1),"En retard",IF(H29>0,"En cours","À faire")))) | J29: =IF(OR(C29="",G29=""),"",G29-TODAY()) | K29: =IF(OR($C29="",$F29="",$G29=""),"",IF(AND($F29<=Paramètres!$C$12+6,$G29>=Paramètres!$C$12),1,"")) | L29: =IF(OR($C29="",$F29="",$G29=""),"",IF(AND($F29<=Paramètres!$C$13+6,$G29>=Paramètres!$C$13),1,"")) | M29: =IF(OR($C29="",$F29="",$G29=""),"",IF(AND($F29<=Paramètres!$C$14+6,$G29>=Paramètres!$C$14),1,"")) | N29: =IF(OR($C29="",$F29="",$G29=""),"",IF(AND($F29<=Paramètres!$C$15+6,$G29>=Paramètres!$C$15),1,"")) | O29: =IF(OR($C29="",$F29="",$G29=""),"",IF(AND($F29<=Paramètres!$C$16+6,$G29>=Paramètres!$C$16),1,"")) | P29: =IF(OR($C29="",$F29="",$G29=""),"",IF(AND($F29<=Paramètres!$C$17+6,$G29>=Paramètres!$C$17),1,"")) | Q29: =IF(OR($C29="",$F29="",$G29=""),"",IF(AND($F29<=Paramètres!$C$18+6,$G29>=Paramètres!$C$18),1,"")) | R29: =IF(OR($C29="",$F29="",$G29=""),"",IF(AND($F29<=Paramètres!$C$19+6,$G29>=Paramètres!$C$19),1,"")) | S29: =IF(OR($C29="",$F29="",$G29=""),"",IF(AND($F29<=Paramètres!$C$20+6,$G29>=Paramètres!$C$20),1,"")) | T29: =IF(OR($C29="",$F29="",$G29=""),"",IF(AND($F29<=Paramètres!$C$21+6,$G29>=Paramètres!$C$21),1,"")) | U29: =IF(OR($C29="",$F29="",$G29=""),"",IF(AND($F29<=Paramètres!$C$22+6,$G29>=Paramètres!$C$22),1,"")) | V29: =IF(OR($C29="",$F29="",$G29=""),"",IF(AND($F29<=Paramètres!$C$23+6,$G29>=Paramètres!$C$23),1,"")) | W29: =IF(OR($C29="",$F29="",$G29=""),"",IF(AND($F29<=Paramètres!$C$24+6,$G29>=Paramètres!$C$24),1,"")) | X29: =IF(OR($C29="",$F29="",$G29=""),"",IF(AND($F29<=Paramètres!$C$25+6,$G29>=Paramètres!$C$25),1,"")) | Y29: =IF(OR($C29="",$F29="",$G29=""),"",IF(AND($F29<=Paramètres!$C$26+6,$G29>=Paramètres!$C$26),1,"")) | Z29: =IF(OR($C29="",$F29="",$G29=""),"",IF(AND($F29<=Paramètres!$C$27+6,$G29>=Paramètres!$C$27),1,""))
B30: TRANSVERSE | C30: Planning blancs complets (2 UE / week-end) | D30: Révision globale | E30: Haute | F30: =Paramètres!$C$5+(12-1)*7 | G30: =Paramètres!$C$5+(15)*7-1 | H30: 0 | I30: =IF(C30="","",IF(H30>=1,"Terminé",IF(AND(G30<>"",G30<TODAY(),H30<1),"En retard",IF(H30>0,"En cours","À faire")))) | J30: =IF(OR(C30="",G30=""),"",G30-TODAY()) | K30: =IF(OR($C30="",$F30="",$G30=""),"",IF(AND($F30<=Paramètres!$C$12+6,$G30>=Paramètres!$C$12),1,"")) | L30: =IF(OR($C30="",$F30="",$G30=""),"",IF(AND($F30<=Paramètres!$C$13+6,$G30>=Paramètres!$C$13),1,"")) | M30: =IF(OR($C30="",$F30="",$G30=""),"",IF(AND($F30<=Paramètres!$C$14+6,$G30>=Paramètres!$C$14),1,"")) | N30: =IF(OR($C30="",$F30="",$G30=""),"",IF(AND($F30<=Paramètres!$C$15+6,$G30>=Paramètres!$C$15),1,"")) | O30: =IF(OR($C30="",$F30="",$G30=""),"",IF(AND($F30<=Paramètres!$C$16+6,$G30>=Paramètres!$C$16),1,"")) | P30: =IF(OR($C30="",$F30="",$G30=""),"",IF(AND($F30<=Paramètres!$C$17+6,$G30>=Paramètres!$C$17),1,"")) | Q30: =IF(OR($C30="",$F30="",$G30=""),"",IF(AND($F30<=Paramètres!$C$18+6,$G30>=Paramètres!$C$18),1,"")) | R30: =IF(OR($C30="",$F30="",$G30=""),"",IF(AND($F30<=Paramètres!$C$19+6,$G30>=Paramètres!$C$19),1,"")) | S30: =IF(OR($C30="",$F30="",$G30=""),"",IF(AND($F30<=Paramètres!$C$20+6,$G30>=Paramètres!$C$20),1,"")) | T30: =IF(OR($C30="",$F30="",$G30=""),"",IF(AND($F30<=Paramètres!$C$21+6,$G30>=Paramètres!$C$21),1,"")) | U30: =IF(OR($C30="",$F30="",$G30=""),"",IF(AND($F30<=Paramètres!$C$22+6,$G30>=Paramètres!$C$22),1,"")) | V30: =IF(OR($C30="",$F30="",$G30=""),"",IF(AND($F30<=Paramètres!$C$23+6,$G30>=Paramètres!$C$23),1,"")) | W30: =IF(OR($C30="",$F30="",$G30=""),"",IF(AND($F30<=Paramètres!$C$24+6,$G30>=Paramètres!$C$24),1,"")) | X30: =IF(OR($C30="",$F30="",$G30=""),"",IF(AND($F30<=Paramètres!$C$25+6,$G30>=Paramètres!$C$25),1,"")) | Y30: =IF(OR($C30="",$F30="",$G30=""),"",IF(AND($F30<=Paramètres!$C$26+6,$G30>=Paramètres!$C$26),1,"")) | Z30: =IF(OR($C30="",$F30="",$G30=""),"",IF(AND($F30<=Paramètres!$C$27+6,$G30>=Paramètres!$C$27),1,""))
B31: TRANSVERSE | C31: Fiches express — formules & schémas | D31: Fiches | E31: Haute | F31: =Paramètres!$C$5+(13-1)*7 | G31: =Paramètres!$C$5+(16)*7-1 | H31: 0 | I31: =IF(C31="","",IF(H31>=1,"Terminé",IF(AND(G31<>"",G31<TODAY(),H31<1),"En retard",IF(H31>0,"En cours","À faire")))) | J31: =IF(OR(C31="",G31=""),"",G31-TODAY()) | K31: =IF(OR($C31="",$F31="",$G31=""),"",IF(AND($F31<=Paramètres!$C$12+6,$G31>=Paramètres!$C$12),1,"")) | L31: =IF(OR($C31="",$F31="",$G31=""),"",IF(AND($F31<=Paramètres!$C$13+6,$G31>=Paramètres!$C$13),1,"")) | M31: =IF(OR($C31="",$F31="",$G31=""),"",IF(AND($F31<=Paramètres!$C$14+6,$G31>=Paramètres!$C$14),1,"")) | N31: =IF(OR($C31="",$F31="",$G31=""),"",IF(AND($F31<=Paramètres!$C$15+6,$G31>=Paramètres!$C$15),1,"")) | O31: =IF(OR($C31="",$F31="",$G31=""),"",IF(AND($F31<=Paramètres!$C$16+6,$G31>=Paramètres!$C$16),1,"")) | P31: =IF(OR($C31="",$F31="",$G31=""),"",IF(AND($F31<=Paramètres!$C$17+6,$G31>=Paramètres!$C$17),1,"")) | Q31: =IF(OR($C31="",$F31="",$G31=""),"",IF(AND($F31<=Paramètres!$C$18+6,$G31>=Paramètres!$C$18),1,"")) | R31: =IF(OR($C31="",$F31="",$G31=""),"",IF(AND($F31<=Paramètres!$C$19+6,$G31>=Paramètres!$C$19),1,"")) | S31: =IF(OR($C31="",$F31="",$G31=""),"",IF(AND($F31<=Paramètres!$C$20+6,$G31>=Paramètres!$C$20),1,"")) | T31: =IF(OR($C31="",$F31="",$G31=""),"",IF(AND($F31<=Paramètres!$C$21+6,$G31>=Paramètres!$C$21),1,"")) | U31: =IF(OR($C31="",$F31="",$G31=""),"",IF(AND($F31<=Paramètres!$C$22+6,$G31>=Paramètres!$C$22),1,"")) | V31: =IF(OR($C31="",$F31="",$G31=""),"",IF(AND($F31<=Paramètres!$C$23+6,$G31>=Paramètres!$C$23),1,"")) | W31: =IF(OR($C31="",$F31="",$G31=""),"",IF(AND($F31<=Paramètres!$C$24+6,$G31>=Paramètres!$C$24),1,"")) | X31: =IF(OR($C31="",$F31="",$G31=""),"",IF(AND($F31<=Paramètres!$C$25+6,$G31>=Paramètres!$C$25),1,"")) | Y31: =IF(OR($C31="",$F31="",$G31=""),"",IF(AND($F31<=Paramètres!$C$26+6,$G31>=Paramètres!$C$26),1,"")) | Z31: =IF(OR($C31="",$F31="",$G31=""),"",IF(AND($F31<=Paramètres!$C$27+6,$G31>=Paramètres!$C$27),1,""))
I32: =IF(C32="","",IF(H32>=1,"Terminé",IF(AND(G32<>"",G32<TODAY(),H32<1),"En retard",IF(H32>0,"En cours","À faire")))) | J32: =IF(OR(C32="",G32=""),"",G32-TODAY()) | K32: =IF(OR($C32="",$F32="",$G32=""),"",IF(AND($F32<=Paramètres!$C$12+6,$G32>=Paramètres!$C$12),1,"")) | L32: =IF(OR($C32="",$F32="",$G32=""),"",IF(AND($F32<=Paramètres!$C$13+6,$G32>=Paramètres!$C$13),1,"")) | M32: =IF(OR($C32="",$F32="",$G32=""),"",IF(AND($F32<=Paramètres!$C$14+6,$G32>=Paramètres!$C$14),1,"")) | N32: =IF(OR($C32="",$F32="",$G32=""),"",IF(AND($F32<=Paramètres!$C$15+6,$G32>=Paramètres!$C$15),1,"")) | O32: =IF(OR($C32="",$F32="",$G32=""),"",IF(AND($F32<=Paramètres!$C$16+6,$G32>=Paramètres!$C$16),1,"")) | P32: =IF(OR($C32="",$F32="",$G32=""),"",IF(AND($F32<=Paramètres!$C$17+6,$G32>=Paramètres!$C$17),1,"")) | Q32: =IF(OR($C32="",$F32="",$G32=""),"",IF(AND($F32<=Paramètres!$C$18+6,$G32>=Paramètres!$C$18),1,"")) | R32: =IF(OR($C32="",$F32="",$G32=""),"",IF(AND($F32<=Paramètres!$C$19+6,$G32>=Paramètres!$C$19),1,"")) | S32: =IF(OR($C32="",$F32="",$G32=""),"",IF(AND($F32<=Paramètres!$C$20+6,$G32>=Paramètres!$C$20),1,"")) | T32: =IF(OR($C32="",$F32="",$G32=""),"",IF(AND($F32<=Paramètres!$C$21+6,$G32>=Paramètres!$C$21),1,"")) | U32: =IF(OR($C32="",$F32="",$G32=""),"",IF(AND($F32<=Paramètres!$C$22+6,$G32>=Paramètres!$C$22),1,"")) | V32: =IF(OR($C32="",$F32="",$G32=""),"",IF(AND($F32<=Paramètres!$C$23+6,$G32>=Paramètres!$C$23),1,"")) | W32: =IF(OR($C32="",$F32="",$G32=""),"",IF(AND($F32<=Paramètres!$C$24+6,$G32>=Paramètres!$C$24),1,"")) | X32: =IF(OR($C32="",$F32="",$G32=""),"",IF(AND($F32<=Paramètres!$C$25+6,$G32>=Paramètres!$C$25),1,"")) | Y32: =IF(OR($C32="",$F32="",$G32=""),"",IF(AND($F32<=Paramètres!$C$26+6,$G32>=Paramètres!$C$26),1,"")) | Z32: =IF(OR($C32="",$F32="",$G32=""),"",IF(AND($F32<=Paramètres!$C$27+6,$G32>=Paramètres!$C$27),1,""))
